python3 KBQA/KBQA/KBQA_backend.py
Traceback (most recent call last):
  File "KBQA/KBQA/KBQA_backend.py", line 4, in <module>
    from flask import Flask, jsonify
ModuleNotFoundError: No module named 'flask'

python3 KBQA/KBQA/KBQA_backend.py
Traceback (most recent call last):
  File "KBQA/KBQA/KBQA_backend.py", line 10, in <module>
    from KBQA.chatbot_graph import *
  File "/home/zhangchunsheng/git/CO-IN/KBQA/KBQA/chatbot_graph.py", line 1, in <module>
    from KBQA.answer_search import *
  File "/home/zhangchunsheng/git/CO-IN/KBQA/KBQA/answer_search.py", line 1, in <module>
    from py2neo import Graph
ModuleNotFoundError: No module named 'py2neo'

python3 KBQA/KBQA/KBQA_backend.py
Traceback (most recent call last):
  File "KBQA/KBQA/KBQA_backend.py", line 10, in <module>
    from KBQA.chatbot_graph import *
  File "/home/zhangchunsheng/git/CO-IN/KBQA/KBQA/chatbot_graph.py", line 2, in <module>
    from KBQA.question_classifier import *
  File "/home/zhangchunsheng/git/CO-IN/KBQA/KBQA/question_classifier.py", line 1, in <module>
    import ahocorasick
ModuleNotFoundError: No module named 'ahocorasick'

python3 KBQA/KBQA/KBQA_backend.py
Traceback (most recent call last):
  File "/usr/local/lib/python3.6/site-packages/py2neo/client/__init__.py", line 806, in acquire
    cx = self._free_list.popleft()
IndexError: pop from an empty deque

During handling of the above exception, another exception occurred:

Traceback (most recent call last):
  File "/usr/local/lib/python3.6/site-packages/py2neo/wiring.py", line 62, in open
    s.connect(address)
ConnectionRefusedError: [Errno 111] Connection refused

The above exception was the direct cause of the following exception:

Traceback (most recent call last):
  File "/usr/local/lib/python3.6/site-packages/py2neo/client/bolt.py", line 355, in open
    wire = cls._connect(profile, on_broken=on_broken)
  File "/usr/local/lib/python3.6/site-packages/py2neo/client/bolt.py", line 369, in _connect
    wire = Wire.open(profile.address, keep_alive=True, on_broken=on_broken)
  File "/usr/local/lib/python3.6/site-packages/py2neo/wiring.py", line 64, in open
    raise_from(WireError("Cannot connect to %r" % (address,)), error)
  File "<string>", line 3, in raise_from
py2neo.wiring.WireError: Cannot connect to IPv4Address(('39.97.124.144', 7687))

The above exception was the direct cause of the following exception:

Traceback (most recent call last):
  File "KBQA/KBQA/KBQA_backend.py", line 10, in <module>
    from KBQA.chatbot_graph import *
  File "/home/zhangchunsheng/git/CO-IN/KBQA/KBQA/chatbot_graph.py", line 2, in <module>
    from KBQA.question_classifier import *
  File "/home/zhangchunsheng/git/CO-IN/KBQA/KBQA/question_classifier.py", line 7, in <module>
    class QuestionClassifier:
  File "/home/zhangchunsheng/git/CO-IN/KBQA/KBQA/question_classifier.py", line 8, in QuestionClassifier
    dc = DictConstructor()
  File "/home/zhangchunsheng/git/CO-IN/KBQA/KBQA/dict_construct.py", line 9, in __init__
    self.graph = Graph(uri, auth=(user, password))
  File "/usr/local/lib/python3.6/site-packages/py2neo/database.py", line 288, in __init__
    self.service = GraphService(profile, **settings)
  File "/usr/local/lib/python3.6/site-packages/py2neo/database.py", line 119, in __init__
    self._connector = Connector(profile, **connector_settings)
  File "/usr/local/lib/python3.6/site-packages/py2neo/client/__init__.py", line 960, in __init__
    self._add_pools(*self._initial_routers)
  File "/usr/local/lib/python3.6/site-packages/py2neo/client/__init__.py", line 988, in _add_pools
    on_broken=self._on_broken)
  File "/usr/local/lib/python3.6/site-packages/py2neo/client/__init__.py", line 649, in open
    seeds = [pool.acquire() for _ in range(init_size or cls.default_init_size)]
  File "/usr/local/lib/python3.6/site-packages/py2neo/client/__init__.py", line 649, in <listcomp>
    seeds = [pool.acquire() for _ in range(init_size or cls.default_init_size)]
  File "/usr/local/lib/python3.6/site-packages/py2neo/client/__init__.py", line 813, in acquire
    cx = self._connect()
  File "/usr/local/lib/python3.6/site-packages/py2neo/client/__init__.py", line 766, in _connect
    on_broken=lambda msg: self.__on_broken(msg))
  File "/usr/local/lib/python3.6/site-packages/py2neo/client/__init__.py", line 175, in open
    on_release=on_release, on_broken=on_broken)
  File "/usr/local/lib/python3.6/site-packages/py2neo/client/bolt.py", line 364, in open
    raise_from(ConnectionUnavailable("Cannot open connection to %r" % profile), error)
  File "<string>", line 3, in raise_from
py2neo.errors.ConnectionUnavailable: Cannot open connection to ConnectionProfile('bolt://39.97.124.144:7687')

sudo docker-compose up redis
WARNING: Found orphan containers (pumpkinjob-agent1, pumpkinjob-agent, pumpkinjob-mysql, pumpkinjob-server, pumpkin-fe, pumpkinjob-mongodb, pumpkinjob-mongo-express) for this project. If you removed or renamed this service in your compose file, you can run this command with the --remove-orphans flag to clean it up.
Starting docker-redis ... done
Attaching to docker-redis
docker-redis | /bin/bash: line 1: /proc/sys/net/core/somaxconn: Read-only file system
docker-redis exited with code 1

neo4jv3_1    | Changed password for user 'neo4j'.
neo4jv3_1    | Active database: graph.db
neo4jv3_1    | Directories in use:
neo4jv3_1    |   home:         /var/lib/neo4j
neo4jv3_1    |   config:       /var/lib/neo4j/conf
neo4jv3_1    |   logs:         /var/lib/neo4j/logs
neo4jv3_1    |   plugins:      /plugins
neo4jv3_1    |   import:       NOT SET
neo4jv3_1    |   data:         /var/lib/neo4j/data
neo4jv3_1    |   certificates: /var/lib/neo4j/certificates
neo4jv3_1    |   run:          /var/lib/neo4j/run
neo4jv3_1    | Starting Neo4j.
docker-mysql | 2022-07-26 02:50:35+00:00 [Note] [Entrypoint]: Database files initialized
docker-mysql | 2022-07-26 02:50:35+00:00 [Note] [Entrypoint]: Starting temporary server
neo4jv3_1    | 2022-07-26 02:50:36.162+0000 WARN  Unknown config option: causal_clustering.discovery_listen_address
neo4jv3_1    | 2022-07-26 02:50:36.166+0000 WARN  Unknown config option: causal_clustering.raft_advertised_address
neo4jv3_1    | 2022-07-26 02:50:36.166+0000 WARN  Unknown config option: causal_clustering.raft_listen_address
neo4jv3_1    | 2022-07-26 02:50:36.166+0000 WARN  Unknown config option: ha.host.coordination
neo4jv3_1    | 2022-07-26 02:50:36.166+0000 WARN  Unknown config option: causal_clustering.transaction_advertised_address
neo4jv3_1    | 2022-07-26 02:50:36.166+0000 WARN  Unknown config option: causal_clustering.discovery_advertised_address
neo4jv3_1    | 2022-07-26 02:50:36.166+0000 WARN  Unknown config option: ha.host.data
neo4jv3_1    | 2022-07-26 02:50:36.166+0000 WARN  Unknown config option: causal_clustering.transaction_listen_address
neo4jv3_1    | 2022-07-26 02:50:36.184+0000 INFO  ======== Neo4j 3.4.0 ========
docker-mysql | 2022-07-26T02:50:36.185473Z 0 [Warning] [MY-010918] [Server] 'default_authentication_plugin' is deprecated and will be removed in a future release. Please use authentication_policy instead.
docker-mysql | 2022-07-26T02:50:36.185504Z 0 [System] [MY-010116] [Server] /usr/sbin/mysqld (mysqld 8.0.27) starting as process 93
docker-mysql | 2022-07-26T02:50:36.212546Z 1 [System] [MY-013576] [InnoDB] InnoDB initialization has started.
neo4jv3_1    | 2022-07-26 02:50:36.225+0000 INFO  Starting...
neo4jv3_1    | 2022-07-26 02:50:36.281+0000 ERROR Failed to start Neo4j: Starting Neo4j failed: Component 'org.neo4j.server.database.LifecycleManagingDatabase@71a794e5' was successfully initialized, but failed to start. Please see the attached cause exception "/var/lib/neo4j/logs/debug.log (Permission denied)". Starting Neo4j failed: Component 'org.neo4j.server.database.LifecycleManagingDatabase@71a794e5' was successfully initialized, but failed to start. Please see
the attached cause exception "/var/lib/neo4j/logs/debug.log (Permission denied)".
neo4jv3_1    | org.neo4j.server.ServerStartupException: Starting Neo4j failed: Component 'org.neo4j.server.database.LifecycleManagingDatabase@71a794e5' was successfully initialized, but failed to start. Please see the attached cause exception "/var/lib/neo4j/logs/debug.log (Permission denied)".
neo4jv3_1    |  at org.neo4j.server.exception.ServerStartupErrors.translateToServerStartupError(ServerStartupErrors.java:68)
neo4jv3_1    |  at org.neo4j.server.AbstractNeoServer.start(AbstractNeoServer.java:220)
neo4jv3_1    |  at org.neo4j.server.ServerBootstrapper.start(ServerBootstrapper.java:111)
neo4jv3_1    |  at org.neo4j.server.ServerBootstrapper.start(ServerBootstrapper.java:79)
neo4jv3_1    |  at org.neo4j.server.CommunityEntryPoint.main(CommunityEntryPoint.java:32)
neo4jv3_1    | Caused by: org.neo4j.kernel.lifecycle.LifecycleException: Component 'org.neo4j.server.database.LifecycleManagingDatabase@71a794e5' was successfully initialized, but failed to start. Please see the attached cause exception "/var/lib/neo4j/logs/debug.log (Permission denied)".
neo4jv3_1    |  at org.neo4j.kernel.lifecycle.LifeSupport$LifecycleInstance.start(LifeSupport.java:466)
neo4jv3_1    |  at org.neo4j.kernel.lifecycle.LifeSupport.start(LifeSupport.java:107)
neo4jv3_1    |  at org.neo4j.server.AbstractNeoServer.start(AbstractNeoServer.java:212)
neo4jv3_1    |  ... 3 more
neo4jv3_1    | Caused by: java.lang.RuntimeException: java.io.FileNotFoundException: /var/lib/neo4j/logs/debug.log (Permission denied)
neo4jv3_1    |  at org.neo4j.kernel.impl.factory.PlatformModule.createLogService(PlatformModule.java:297)
neo4jv3_1    |  at org.neo4j.kernel.impl.factory.PlatformModule.<init>(PlatformModule.java:161)
neo4jv3_1    |  at org.neo4j.kernel.impl.factory.GraphDatabaseFacadeFactory.createPlatform(GraphDatabaseFacadeFactory.java:245)
neo4jv3_1    |  at org.neo4j.kernel.impl.factory.GraphDatabaseFacadeFactory.initFacade(GraphDatabaseFacadeFactory.java:157)
neo4jv3_1    |  at org.neo4j.kernel.impl.factory.GraphDatabaseFacadeFactory.newFacade(GraphDatabaseFacadeFactory.java:125)
neo4jv3_1    |  at org.neo4j.server.CommunityNeoServer.lambda$static$0(CommunityNeoServer.java:58)
neo4jv3_1    |  at org.neo4j.server.database.LifecycleManagingDatabase.start(LifecycleManagingDatabase.java:88)
neo4jv3_1    |  at org.neo4j.kernel.lifecycle.LifeSupport$LifecycleInstance.start(LifeSupport.java:445)
neo4jv3_1    |  ... 5 more
neo4jv3_1    | Caused by: java.io.FileNotFoundException: /var/lib/neo4j/logs/debug.log (Permission denied)
neo4jv3_1    |  at java.io.FileOutputStream.open0(Native Method)
neo4jv3_1    |  at java.io.FileOutputStream.open(FileOutputStream.java:270)
neo4jv3_1    |  at java.io.FileOutputStream.<init>(FileOutputStream.java:213)
neo4jv3_1    |  at org.neo4j.io.fs.DefaultFileSystemAbstraction.openAsOutputStream(DefaultFileSystemAbstraction.java:76)
neo4jv3_1    |  at org.neo4j.io.file.Files.createOrOpenAsOutputStream(Files.java:51)
neo4jv3_1    |  at org.neo4j.logging.RotatingFileOutputStreamSupplier.openOutputFile(RotatingFileOutputStreamSupplier.java:338)
neo4jv3_1    |  at org.neo4j.logging.RotatingFileOutputStreamSupplier.<init>(RotatingFileOutputStreamSupplier.java:137)
neo4jv3_1    |  at org.neo4j.logging.RotatingFileOutputStreamSupplier.<init>(RotatingFileOutputStreamSupplier.java:121)
neo4jv3_1    |  at org.neo4j.kernel.impl.logging.StoreLogService.<init>(StoreLogService.java:180)
neo4jv3_1    |  at org.neo4j.kernel.impl.logging.StoreLogService.<init>(StoreLogService.java:44)
neo4jv3_1    |  at org.neo4j.kernel.impl.logging.StoreLogService$Builder.build(StoreLogService.java:124)
neo4jv3_1    |  at org.neo4j.kernel.impl.factory.PlatformModule.createLogService(PlatformModule.java:293)
neo4jv3_1    |  ... 12 more
neo4jv3_1    | 2022-07-26 02:50:36.283+0000 INFO  Neo4j Server shutdown initiated by request
